<?xml version="1.0"?>

<robot xmlns:xacro="http://www.ros.org/wiki/xacro" >
  
  <xacro:include filename="$(find rover_sim)/description/ros2_control.xacro"/>
  
  <!-- Base footprint - ground reference -->
  <link name="base_footprint"/>

  <joint name="base_joint" type="fixed">
    <parent link="base_footprint"/>
    <child link="base_link"/>
    <origin xyz="0 0 0.06825" rpy="0 0 0"/>
  </joint>

  <link name="base_link">
    <visual>
      <origin xyz="0 0 0.0" rpy="0 0 0"/>
      <geometry>
        <box size="0.2 0.211 0.0965"/>
      </geometry>
      <material name="blue">
        <color rgba="0.2 0.2 0.8 1.0"/>
      </material>
    </visual>
    
    <collision>
      <origin xyz="0 0 0" rpy="0 0 0"/>
      <geometry>
        <box size="0.2 0.15 0.045"/>
      </geometry>
    </collision>
 
    <inertial>
      <origin xyz="0 0 0" rpy="0 0 0"/>
      <mass value="5.0"/>
      <inertia ixx="0.0306" iyy="0.0881" izz="0.1151"
               ixy="0" ixz="0" iyz="0"/>
    </inertial>
  </link>

  <!-- Front Left Wheel -->
  <joint name="front_left_wheel_joint" type="continuous">
    <parent link="base_link"/>
    <child link="front_left_wheel"/>
    <origin xyz="0.05 0.119 -0.03825" rpy="0 0 0"/>
    <axis xyz="0 1 0"/>
  </joint>

  <link name="front_left_wheel">
    <visual>
      <origin xyz="0 0 0" rpy="1.5708 0 0"/>
      <geometry>
        <cylinder radius="0.0325" length="0.027"/>
      </geometry>
      <material name="wheel_color">
        <color rgba="0.1 0.1 0.1 1.0"/>
      </material>
    </visual>
    
    <collision>
      <origin xyz="0 0 0" rpy="1.5708 0 0"/>
      <geometry>
        <cylinder radius="0.0325" length="0.027"/>
      </geometry>
    </collision>
    
    <inertial>
      <origin xyz="0 0 0" rpy="1.5708 0 0"/>
      <mass value="0.01"/>
      <inertia ixx="0.000001" iyy="0.000001" izz="0.000001"
               ixy="0" ixz="0" iyz="0"/>
    </inertial>
  </link>

  <!-- Front Right Wheel -->
  <joint name="front_right_wheel_joint" type="continuous">
    <parent link="base_link"/>
    <child link="front_right_wheel"/>
    <origin xyz="0.05 -0.119 -0.03825" rpy="0 0 0"/>
    <axis xyz="0 1 0"/>
  </joint>

  <link name="front_right_wheel">
    <visual>
      <origin xyz="0 0 0" rpy="1.5708 0 0"/>
      <geometry>
        <cylinder radius="0.0325" length="0.027"/>
      </geometry>
      <material name="wheel_color">
        <color rgba="0.1 0.1 0.1 1.0"/>
      </material>
    </visual>
    
    <collision>
      <origin xyz="0 0 0" rpy="1.5708 0 0"/>
      <geometry>
        <cylinder radius="0.0325" length="0.027"/>
      </geometry>
    </collision>
    
    <inertial>
      <origin xyz="0 0 0" rpy="1.5708 0 0"/>
      <mass value="0.01"/>
      <inertia ixx="0.000001" iyy="0.000001" izz="0.000001"
               ixy="0" ixz="0" iyz="0"/>
    </inertial>
  </link>

  <!-- Back Left Wheel -->
  <joint name="back_left_wheel_joint" type="continuous">
    <parent link="base_link"/>
    <child link="back_left_wheel"/>
    <origin xyz="-0.05 0.119 -0.03825" rpy="0 0 0"/>
    <axis xyz="0 1 0"/>
  </joint>

  <link name="back_left_wheel">
    <visual>
      <origin xyz="0 0 0" rpy="1.5708 0 0"/>
      <geometry>
        <cylinder radius="0.0325" length="0.027"/>
      </geometry>
      <material name="wheel_color">
        <color rgba="0.1 0.1 0.1 1.0"/>
      </material>
    </visual>
    
    <collision>
      <origin xyz="0 0 0" rpy="1.5708 0 0"/>
      <geometry>
        <cylinder radius="0.0325" length="0.027"/>
      </geometry>
    </collision>
    
    <inertial>
      <origin xyz="0 0 0" rpy="1.5708 0 0"/>
      <mass value="0.01"/>
      <inertia ixx="0.000001" iyy="0.000001" izz="0.000001"
               ixy="0" ixz="0" iyz="0"/>
    </inertial>
  </link>

  <!-- Back Right Wheel -->
  <joint name="back_right_wheel_joint" type="continuous">
    <parent link="base_link"/>
    <child link="back_right_wheel"/>
    <origin xyz="-0.05 -0.119 -0.03825" rpy="0 0 0"/>
    <axis xyz="0 1 0"/>
  </joint>

  <link name="back_right_wheel">
    <visual>
      <origin xyz="0 0 0" rpy="1.5708 0 0"/>
      <geometry>
        <cylinder radius="0.0325" length="0.027"/>
      </geometry>
      <material name="wheel_color">
        <color rgba="0.1 0.1 0.1 1.0"/>
      </material>
    </visual>
    
    <collision>
      <origin xyz="0 0 0" rpy="1.5708 0 0"/>
      <geometry>
        <cylinder radius="0.0325" length="0.027"/>
      </geometry>
    </collision>
    
    <inertial>
      <origin xyz="0 0 0" rpy="1.5708 0 0"/>
      <mass value="0.01"/>
      <inertia ixx="0.000001" iyy="0.000001" izz="0.000001"
               ixy="0" ixz="0" iyz="0"/>
    </inertial>
  </link>

</robot>
